<?xml version="1.0"?>
<robot xmlns:xacro="http://www.ros.org/wiki/xacro" name="lidar_robot">

    <link name="base_footprint"/>

    <joint name="base_joint" type="fixed">
        <parent link="base_footprint"/>
        <child link="base_link"/>
        <origin xyz="0 0 0.034"/>
    </joint>


    <link name="base_link">
        <visual>
            <geometry>
                <mesh filename="package://urdf_oneday/meshes/visual/base_link.dae"/>
            </geometry>
        </visual>

        <collision>
            <geometry>
                <mesh filename="package://urdf_oneday/meshes/collision/base_link.stl"/>
            </geometry>
        </collision>
        
    </link>

    <!-- LEFT WHEEL LINK -->
    <joint name="l_wheel_joint" type="continuous">
        <parent link="base_link"/>
        <child link="l_wheel"/>
        <origin xyz="0 0.09 0" rpy="0 0 -${pi/2}" />
        <axis xyz="-1 0 0"/>
    </joint>

    <link name="l_wheel">
        <visual>
            <geometry>
                <mesh filename="package://urdf_oneday/meshes/visual/wheel.dae"/>
            </geometry>
        </visual>

        <collision>
            <geometry>
                <mesh filename="package://urdf_oneday/meshes/collision/wheel.stl"/>
            </geometry>
        </collision>

    </link>

    <!-- RIGHT WHEEL LINK -->
    <joint name="r_wheel_joint" type="continuous">
        <parent link="base_link"/>
        <child link="r_wheel"/>
        <origin xyz="0 -0.09 0" rpy="0 0 ${pi/2}" />
        <axis xyz="1 0 0"/>
    </joint>

    <link name="r_wheel">
        <visual>
            <geometry>
                <mesh filename="package://urdf_oneday/meshes/visual/wheel.dae"/>
            </geometry>
        </visual>

        <collision>
            <geometry>
                <mesh filename="package://urdf_oneday/meshes/collision/wheel.stl"/>
            </geometry>
        </collision>
    </link>

    <!-- CAMERA LINK -->
    <joint name="camera_mount_joint" type="fixed">
        <parent link="base_link"/>
        <child link="camera_mount"/>
        <origin xyz="0.045 0 0.080" rpy="0 0 0" />
    </joint>

    <link name="camera_mount">
        <visual>
            <geometry>
                <mesh filename="package://urdf_oneday/meshes/visual/front_camera.dae"/>
            </geometry>
        </visual>

        <collision>
            <geometry>
                <mesh filename="package://urdf_oneday/meshes/collision/front_camera.stl"/>
            </geometry>
        </collision>

    </link>

    <joint name="camera_joint" type="fixed">
        <parent link="camera_mount"/>
        <child link="camera"/>
        <origin xyz="0.0111 0 0.0193" rpy="0 1.5708 0" />
    </joint>

    <link name="camera">
    </link>

    <!-- LIDAR LINK -->
    <joint name="lidar_mount_joint" type="fixed">
        <parent link="base_link"/>
        <child link="lidar_mount"/>
        <origin xyz="-0.01 0 0.080" rpy="0 0 0" />
    </joint>

    <link name="lidar_mount">
        <visual>
            <geometry>
                <mesh filename="package://urdf_oneday/meshes/visual/ydlidar_x2_assy.dae"/>
            </geometry>
        </visual>

        <collision>
            <geometry>
                <mesh filename="package://urdf_oneday/meshes/collision/ydlidar_x2_assy.stl"/>
            </geometry>
        </collision>
    </link>

    <joint name="lidar_joint" type="fixed">
        <parent link="lidar_mount"/>
        <child link="lidar"/>
        <origin xyz="0 0 0.04245" rpy="0 0 0" />
    </joint>

    <link name="lidar">
    </link>

    <!-- UL SENSOR -->
    <joint name="ul_sensor_mount_joint" type="fixed">
        <parent link="base_link"/>
        <child link="ul_sensor_mount"/>
        <origin xyz="0.03 0 0.01" rpy="0 0 0" />
    </joint>

    <link name="ul_sensor_mount">
        <visual>
            <geometry>
                <mesh filename="package://urdf_oneday/meshes/visual/ul_sensor.dae"/>
            </geometry>
        </visual>

        <collision>
            <geometry>
                <mesh filename="package://urdf_oneday/meshes/collision/ul_sensor.stl"/>
            </geometry>
        </collision>

    </link>

    <joint name="ul_sensor_joint" type="fixed">
        <parent link="ul_sensor_mount"/>
        <child link="ul_sensor"/>
        <origin xyz="0.02 0 0" rpy="0 0 0" />
    </joint>

    <link name="ul_sensor">
    </link>
</robot>